Workbook

Sheet Tabel_Perhitungan
A1: TABEL PERHITUNGAN KETAATAN JAM KERJA PEGAWAI NEGERI SIPIL
A3: PERANGKAT DAERAH | D3: : BADAN KEPEGAWAIAN DAN PENGEMBAGAN SUMBER DAYA MANUSIA
A4: BULAN | D4: : AGUSTUS 2026
A6: NO | B6: NAMA/NIP | C6: PANGKAT/GOL. RUANG | D6: JABATAN | E6: JUMLAH HARI KERJA | F6: JUMLAH HARI TIDAK MASUK KERJA | Q6: PERHITUNGAN % KETIDAKTAATAN JAM KERJA
F7: TB | J7: PC | N7: TDK | O7: I | P7: A | Q7: TB | U7: PC | Y7: TDK | Z7: I | AA7: A | AB7: JML
F8: Tb 1 | G8: Tb 2 | H8: Tb 3 | I8: Tb 4 | J8: Pc 1 | K8: Pc 2 | L8: Pc 3 | M8: Pc 4 | N8: Dialog/Apel/Upacara | Q8: P1 | R8: P2 | S8: P3 | T8: P4 | U8: Pc 1 | V8: Pc 2 | W8: Pc 3 | X8: Pc 4 | Y8: Dialog/Apel/Upacara
F9: menit | G9: menit | H9: menit | I9: menit | J9: menit | K9: menit | L9: menit | M9: menit | N9: Perkeg | O9: hari | P9: hari | Q9: 0.005 | R9: 0.01 | S9: 1.25% | T9: 1.5% | U9: 0.5% | V9: 0.01 | W9: 1.25% | X9: 1.5% | Y9: 0.02 | Z9: 0 | AA9: 0.03
A10: 1 | B10: 2 | C10: 3 | D10: 4 | E10: 5 | F10: 6 | G10: 7 | H10: 8 | I10: 9 | J10: 10 | K10: 11 | L10: 12 | M10: 13 | N10: 14 | O10: 15 | P10: 16 | Q10: 17 | R10: 18 | S10: 19 | T10: 20 | U10: 21 | V10: 22 | W10: 23 | X10: 24 | Y10: 25 | Z10: 26 | AA10: 27 | AB10: 28
A12: 1 | B12: ANDI HIZBULLAH MASTAR, SKM., M.Kes | C12: Pembina Tk.I/IVb | D12: Kepala BKPSDM | E12: 19 | F12: 0 | G12: 0 | H12: 0 | I12: 0 | J12: 0 | K12: 0 | L12: 0 | M12: 0 | N12: 0 | O12: 0 | P12: 0 | Q12: =SUM(F12*0.5%) -> 0 | R12: =SUM(G12*1%) -> 0 | S12: =SUM(H12*1.25%) -> 0 | T12: =SUM(I12*1.5%) -> 0 | U12: =SUM(J12*0.5%) -> 0 | V12: =SUM(K12*1%) -> 0 | W12: =SUM(L12*1.25%) -> 0 | X12: =SUM(M12*1.5%) -> 0 | Y12: =SUM(N12*2%) -> 0 | Z12: =SUM(O12*0%) -> 0 | AA12: =SUM(P12*3%) -> 0 | AB12: =SUM(Q12:AA12) -> 0
B13: Nip.197601072003121007
A14: 2 | B14: Drs. SARIANTO | C14: Pembina Tk.I/IVb | D14: Sekretaris BKPSDM | E14: 19 | F14: 0 | G14: 0 | H14: 0 | I14: 0 | J14: 0 | K14: 0 | L14: 0 | M14: 0 | N14: 0 | O14: 0 | P14: 0 | Q14: =SUM(F14*0.5%) -> 0 | R14: =SUM(G14*1%) -> 0 | S14: =SUM(H14*1.25%) -> 0 | T14: =SUM(I14*1.5%) -> 0 | U14: =SUM(J14*0.5%) -> 0 | V14: =SUM(K14*1%) -> 0 | W14: =SUM(L14*1.25%) -> 0 | X14: =SUM(M14*1.5%) -> 0 | Y14: =SUM(N14*2%) -> 0 | Z14: =SUM(O14*0%) -> 0 | AA14: =SUM(P14*3%) -> 0 | AB14: =SUM(Q14:AA14) -> 0
B15: Nip.197207051992031005
A16: 3 | B16: MUHAMMAD BAHRUM.S.Sos | C16: Pembina/IVa | D16: Kabid. Amidnistrasi Kepegawaian | E16: 19 | F16: 0 | G16: 0 | H16: 0 | I16: 0 | J16: 0 | K16: 0 | L16: 0 | M16: 0 | N16: 0 | O16: 0 | P16: 0 | Q16: 0 | R16: =SUM(G16*1%) -> 0 | S16: =SUM(H16*1.25%) -> 0 | T16: =SUM(I16*1.5%) -> 0 | U16: =SUM(J16*0.5%) -> 0 | V16: =SUM(K16*1%) -> 0 | W16: =SUM(L16*1.25%) -> 0 | X16: =SUM(M16*1.5%) -> 0 | Y16: =SUM(N16*2%) -> 0 | Z16: =SUM(O16*0%) -> 0 | AA16: =SUM(P16*3%) -> 0 | AB16: =SUM(Q16:AA16) -> 0
B17: Nip.198110282000031001
A18: 4 | B18: ZETH DIANTO N.G, S.IP, M.Si | C18: Pembina/IVa | D18: Ka. Bidang Pengadaan, Informasi & Kinerja Pegawai | E18: 19 | F18: 0 | G18: 0 | H18: 0 | I18: 0 | J18: 0 | K18: 0 | L18: 0 | M18: 0 | N18: 0 | O18: 0 | P18: 0 | Q18: =SUM(F18*0.5%) -> 0 | R18: =SUM(G18*1%) -> 0 | S18: =SUM(H18*1.25%) -> 0 | T18: =SUM(I18*1.5%) -> 0 | U18: =SUM(J18*0.5%) -> 0 | V18: =SUM(K18*1%) -> 0 | W18: =SUM(L18*1.25%) -> 0 | X18: =SUM(M18*1.5%) -> 0 | Y18: =SUM(N18*2%) -> 0 | Z18: =SUM(O18*0%) -> 0 | AA18: =SUM(P18*3%) -> 0 | AB18: =SUM(Q18:AA18) -> 0
B19: Nip. 197411071993031003
A20: 5 | B20: MUHAMMAD NARWIS, S.STP., MA. | C20: Pembina/IVa | D20: Ka. Bidang Pendidikan & Pelatihan | E20: 19 | F20: 0 | G20: 0 | H20: 0 | I20: 0 | J20: 0 | K20: 0 | L20: 0 | M20: 0 | N20: 0 | O20: 4 | P20: 0 | Q20: =SUM(F20*0.5%) -> 0 | R20: =SUM(G20*1%) -> 0 | S20: =SUM(H20*1.25%) -> 0 | T20: =SUM(I20*1.5%) -> 0 | U20: =SUM(J20*0.5%) -> 0 | V20: =SUM(K20*1%) -> 0 | W20: =SUM(L20*1.25%) -> 0 | X20: =SUM(M20*1.5%) -> 0 | Y20: =SUM(N20*2%) -> 0 | Z20: =SUM(O20*0%) -> 0 | AA20: =SUM(P20*3%) -> 0 | AB20: =SUM(Q20:AA20) -> 0
B21: Nip. 198610182006021001
A22: 6 | B22: ANDI SYAMSIAH, SE | C22: Penata Tk.I/IIId | D22: Ka. Sub. Bagian Keuangan, Perencanaan & Pelaporan | E22: 19 | F22: 0 | G22: 0 | H22: 0 | I22: 0 | J22: 0 | K22: 0 | L22: 0 | M22: 0 | N22: 0 | O22: 0 | P22: 0 | Q22: =SUM(F22*0.5%) -> 0 | R22: =SUM(G22*1%) -> 0 | S22: =SUM(H22*1.25%) -> 0 | T22: =SUM(I22*1.5%) -> 0 | U22: =SUM(J22*0.5%) -> 0 | V22: =SUM(K22*1%) -> 0 | W22: =SUM(L22*1.25%) -> 0 | X22: =SUM(M22*1.5%) -> 0 | Y22: =SUM(N22*2%) -> 0 | Z22: =SUM(O22*0%) -> 0 | AA22: =SUM(P22*3%) -> 0 | AB22: =SUM(Q22:AA22) -> 0
B23: Nip.197408082006042026
A24: 7 | B24: AKHSAN, S.IP | C24: Penata Tk.I/IIId | D24: Plt. Ka. Sub. Bagian Umum & Kepegawaian | E24: 19 | F24: 0 | G24: 0 | H24: 0 | I24: 0 | J24: 0 | K24: 0 | L24: 0 | M24: 0 | N24: 0 | O24: 0 | P24: 0 | Q24: 0 | R24: =SUM(G24*1%) -> 0 | S24: =SUM(H24*1.25%) -> 0 | T24: =SUM(I24*1.5%) -> 0 | U24: =SUM(J24*0.5%) -> 0 | V24: =SUM(K24*1%) -> 0 | W24: =SUM(L24*1.25%) -> 0 | X24: =SUM(M24*1.5%) -> 0 | Y24: =SUM(N24*2%) -> 0 | Z24: =SUM(O24*0%) -> 0 | AA24: =SUM(P24*3%) -> 0 | AB24: =SUM(Q24:AA24) -> 0
B25: Nip.197612312007011093
A26: 8 | B26: R I D W A N, S.Sos | C26: Penata Tk.I/IIId | D26: Analis SDM Aparatur Ahli Madya | E26: 19 | F26: 0 | G26: 0 | H26: 0 | I26: 0 | J26: 0 | K26: 0 | L26: 0 | M26: 0 | N26: 0 | O26: 0 | P26: 0 | Q26: =SUM(F26*0.5%) -> 0 | R26: =SUM(G26*1%) -> 0 | S26: =SUM(H26*1.25%) -> 0 | T26: =SUM(I26*1.5%) -> 0 | U26: =SUM(J26*0.5%) -> 0 | V26: =SUM(K26*1%) -> 0 | W26: =SUM(L26*1.25%) -> 0 | X26: =SUM(M26*1.5%) -> 0 | Y26: =SUM(N26*2%) -> 0 | Z26: =SUM(O26*0%) -> 0 | AA26: =SUM(P26*3%) -> 0 | AB26: =SUM(Q26:AA26) -> 0
B27: Nip.196909121994031008
A28: 9 | B28: AMIR SAPIRIHAR, S.Sos | C28: Pembina/IVa | D28: Analis SDM Aparatur Ahli Madya | E28: 19 | F28: 0 | G28: 0 | H28: 0 | I28: 0 | J28: 0 | K28: 0 | L28: 0 | M28: 0 | N28: 0 | O28: 0 | P28: 0 | Q28: 0 | R28: =SUM(G28*1%) -> 0 | S28: =SUM(H28*1.25%) -> 0 | T28: =SUM(I28*1.5%) -> 0 | U28: =SUM(J28*0.5%) -> 0 | V28: =SUM(K28*1%) -> 0 | W28: =SUM(L28*1.25%) -> 0 | X28: =SUM(M28*1.5%) -> 0 | Y28: =SUM(N28*2%) -> 0 | Z28: =SUM(O28*0%) -> 0 | AA28: =SUM(P28*3%) -> 0 | AB28: =SUM(Q28:AA28) -> 0
B29: Nip.196804242000031013
A30: 10 | B30: ARY ARFAN, SAP, M.Si | C30: Penata Tk.I/IIId | D30: Analis Pengembangan Kompetensi Aparatur Sipil Negara Ahli Muda | E30: 19 | F30: 0 | G30: 1 | H30: 3 | I30: 0 | J30: 0 | K30: 0 | L30: 0 | M30: 2 | N30: 0 | O30: 0 | P30: 0 | Q30: =SUM(F30*0.5%) -> 0 | R30: =SUM(G30*1%) -> 0.01 | S30: =SUM(H30*1.25%) -> 0.0375 | T30: =SUM(I30*1.5%) -> 0 | U30: =SUM(J30*0.5%) -> 0 | V30: =SUM(K30*1%) -> 0 | W30: =SUM(L30*1.25%) -> 0 | X30: =SUM(M30*1.5%) -> 0.03 | Y30: =SUM(N30*2%) -> 0 | Z30: =SUM(O30*0%) -> 0 | AA30: =SUM(P30*3%) -> 0 | AB30: =SUM(Q30:AA30) -> 0.0775
B31: Nip.198304082008011011
A32: 11 | B32: MUKTI FAHDIANSYAH, S.STP | C32: Pembina/IVa | D32: Analis SDM Aparatur Ahli Madya | E32: 19 | F32: 0 | G32: 0 | H32: 0 | I32: 0 | J32: 0 | K32: 0 | L32: 0 | M32: 2 | N32: 0 | O32: 1 | P32: 0 | Q32: =SUM(F32*0.5%) -> 0 | R32: =SUM(G32*1%) -> 0 | S32: =SUM(H32*1.25%) -> 0 | T32: =SUM(I32*1.5%) -> 0 | U32: =SUM(J32*0.5%) -> 0 | V32: =SUM(K32*1%) -> 0 | W32: =SUM(L32*1.25%) -> 0 | X32: =SUM(M32*1.5%) -> 0.03 | Y32: =SUM(N32*2%) -> 0 | Z32: =SUM(O32*0%) -> 0 | AA32: =SUM(P32*3%) -> 0 | AB32: =SUM(Q32:AA32) -> 0.03
B33: Nip.198608032006021001
A34: 12 | B34: KHALIL ACO, S.Sos | C34: Penata Tk.I/IIId | D34: Analis Pengembangan Karir pada Sub Bidang Kepangkatan | E34: 19 | F34: 2 | G34: 1 | H34: 1 | I34: 0 | J34: 1 | K34: 0 | L34: 0 | M34: 1 | N34: 0 | O34: 0 | P34: 0 | Q34: =SUM(F34*0.5%) -> 0.01 | R34: =SUM(G34*1%) -> 0.01 | S34: =SUM(H34*1.25%) -> 0.0125 | T34: =SUM(I34*1.5%) -> 0 | U34: =SUM(J34*0.5%) -> 0.005 | V34: =SUM(K34*1%) -> 0 | W34: =SUM(L34*1.25%) -> 0 | X34: =SUM(M34*1.5%) -> 0.015 | Y34: =SUM(N34*2%) -> 0 | Z34: =SUM(O34*0%) -> 0 | AA34: =SUM(P34*3%) -> 0 | AB34: =SUM(Q34:AA34) -> 0.0525
B35: Nip.196912311994031108
A36: 13 | B36: A I D I L, S.Sos | C36: Penata Tk.I/IIId | D36: Pranata Sidik Jari pada Sub Bidang Pembinaan Disiplin dan Kinerja | E36: 19 | F36: 0 | G36: 0 | H36: 0 | I36: 0 | J36: 0 | K36: 0 | L36: 0 | M36: 0 | N36: 0 | O36: 0 | P36: 19 | Q36: =SUM(F36*0.5%) -> 0 | R36: =SUM(G36*1%) -> 0 | S36: =SUM(H36*1.25%) -> 0 | T36: =SUM(I36*1.5%) -> 0 | U36: =SUM(J36*0.5%) -> 0 | V36: =SUM(K36*1%) -> 0 | W36: =SUM(L36*1.25%) -> 0 | X36: =SUM(M36*1.5%) -> 0 | Y36: =SUM(N36*2%) -> 0 | Z36: =SUM(O36*0%) -> 0 | AA36: =SUM(P36*3%) -> 0.57 | AB36: =SUM(Q36:AA36) -> 0.57
B37: Nip.196901191996031005
A38: 14 | B38: NASMAH H, SIP | C38: Penata Tk.I/IIId | D38: Analis Sumber Daya Manusia Aparatur Ahli Muda | E38: 19 | F38: 0 | G38: 0 | H38: 0 | I38: 0 | J38: 0 | K38: 0 | L38: 0 | M38: 2 | N38: 0 | O38: 0 | P38: 0 | Q38: =SUM(F38*0.5%) -> 0 | R38: =SUM(G38*1%) -> 0 | S38: =SUM(H38*1.25%) -> 0 | T38: =SUM(I38*1.5%) -> 0 | U38: =SUM(J38*0.5%) -> 0 | V38: =SUM(K38*1%) -> 0 | W38: =SUM(L38*1.25%) -> 0 | X38: =SUM(M38*1.5%) -> 0.03 | Y38: =SUM(N38*2%) -> 0 | Z38: =SUM(O38*0%) -> 0 | AA38: =SUM(P38*3%) -> 0 | AB38: =SUM(Q38:AA38) -> 0.03
B39: Nip.198008142007012008
A40: 15 | B40: A. DWI NUNGRAENI,S.Sos | C40: Penata Tk.I/IIId | D40: Analis Kinerja | E40: 19 | F40: 0 | G40: 0 | H40: 1 | I40: 2 | J40: 0 | K40: 0 | L40: 0 | M40: 2 | N40: 0 | O40: 0 | P40: 1 | Q40: =SUM(F40*0.5%) -> 0 | R40: =SUM(G40*1%) -> 0 | S40: =SUM(H40*1.25%) -> 0.0125 | T40: =SUM(I40*1.5%) -> 0.03 | U40: =SUM(J40*0.5%) -> 0 | V40: =SUM(K40*1%) -> 0 | W40: =SUM(L40*1.25%) -> 0 | X40: =SUM(M40*1.5%) -> 0.03 | Y40: =SUM(N40*2%) -> 0 | Z40: =SUM(O40*0%) -> 0 | AA40: =SUM(P40*3%) -> 0.03 | AB40: =SUM(Q40:AA40) -> 0.1025
B41: Nip.198407292003122002
A42: 16 | B42: SAHARUNA, S.IP | C42: Penata Tk.I/IIId | D42: Analis Pengembangan Karir | E42: 19 | F42: 0 | G42: 2 | H42: 0 | I42: 1 | J42: 0 | K42: 0 | L42: 0 | M42: 1 | N42: 0 | O42: 0 | P42: 0 | Q42: =SUM(F42*0.5%) -> 0 | R42: =SUM(G42*1%) -> 0.02 | S42: =SUM(H42*1.25%) -> 0 | T42: =SUM(I42*1.5%) -> 0.015 | U42: =SUM(J42*0.5%) -> 0 | V42: =SUM(K42*1%) -> 0 | W42: =SUM(L42*1.25%) -> 0 | X42: =SUM(M42*1.5%) -> 0.015 | Y42: =SUM(N42*2%) -> 0 | Z42: =SUM(O42*0%) -> 0 | AA42: =SUM(P42*3%) -> 0 | AB42: =SUM(Q42:AA42) -> 0.05
B43: Nip.198001282007011013
...

Sheet PK PNS
B1: TABEL PERHITUNGAN PRODUKTIVITAS KERJA PEGAWAI NEGERI SIPIL
A3: PERANGKAT DAERAH | C3: : BADAN KEPEGAWAIAN DAN PENGEMBAGAN SUMBER DAYA MANUSIA
A4: BULAN | C4: : AGUSTUS 2026
A6: NO | B6: NAMA/NIP | C6: PANGKAT/GOL. RUANG | D6: JABATAN | E6: JUMLAH WKE | F6: PRODUKTIVITAS KERJA | I6: % TPP DARI UNSUR PRODUKTIVITAS
F7: HASIL KERJA | G7: PERILAKU | H7: RATING
A8: 1 | B8: 2 | C8: 3 | D8: 4 | E8: 5 | F8: 6 | G8: 7 | H8: 8 | I8: 9
A10: 1 | B10: ANDI HIZBULLAH MASTAR, SKM., M.Kes | C10: Pembina Tk.I/IVb | D10: Kepala BKPSDM | E10: 9020 | F10: SESUAI EKSEPEKTASI | G10: BAIK | H10: BAIK | I10: 1
B11: Nip.197601072003121007
A12: 2 | B12: Drs. SARIANTO | C12: Pembina Tk.I/IVb | D12: Sekretaris BKPSDM | E12: 8460 | F12: SESUAI EKSEPEKTASI | G12: BAIK | H12: BAIK | I12: 1
B13: Nip.197207051992031005
A14: 3 | B14: MUHAMMAD BAHRUM.S.Sos | C14: Pembina/IVa | D14: Kabid. Amidnistrasi Kepegawaian | E14: 8400 | F14: SESUAI EKSEPEKTASI | G14: BAIK | H14: BAIK | I14: 1
B15: Nip.198110282000031001
A16: 4 | B16: ZETH DIANTO N.G, S.IP, M.Si | C16: Pembina/IVa | D16: Ka. Bidang Pengadaan, Informasi & Kinerja Pegawai | E16: 6870 | F16: SESUAI EKSEPEKTASI | G16: BAIK | H16: BAIK | I16: 1
B17: Nip. 197411071993031003
A18: 5 | B18: MUHAMMAD NARWIS, S.STP., MA. | C18: Pembina/IVa | D18: Ka. Bidang Pendidikan & Pelatihan | E18: 7643 | F18: SESUAI EKSEPEKTASI | G18: BAIK | H18: BAIK | I18: 1
B19: Nip. 198610182006021001
A20: 6 | B20: ANDI SYAMSIAH, SE | C20: Penata Tk.I/IIId | D20: Ka. Sub. Bagian Keuangan, Perencanaan & Pelaporan | E20: 7400 | F20: SESUAI EKSEPEKTASI | G20: BAIK | H20: BAIK | I20: 1
B21: Nip.197408082006042026
A22: 7 | B22: AKHSAN, S.IP | C22: Penata Tk.I/IIId | D22: Plt. Ka. Sub. Bagian Umum & Kepegawaian | E22: 7700 | F22: SESUAI EKSEPEKTASI | G22: BAIK | H22: BAIK | I22: 1
B23: Nip.197612312007011093
A24: 8 | B24: R I D W A N, S.Sos | C24: Penata Tk.I/IIId | D24: Analis SDM Aparatur Ahli Madya | E24: 7870 | F24: SESUAI EKSEPEKTASI | G24: BAIK | H24: BAIK | I24: 1
B25: Nip.196909121994031008
A26: 9 | B26: AMIR SAPIRIHAR, S.Sos | C26: Pembina/IVa | D26: Analis SDM Aparatur Ahli Madya | E26: 7025 | F26: SESUAI EKSEPEKTASI | G26: BAIK | H26: BAIK | I26: 1
B27: Nip.196804242000031013
A28: 10 | B28: ARY ARFAN, SAP, M.Si | C28: Penata Tk.I/IIId | D28: Analis Pengembangan Kompetensi Aparatur Sipil Negara Ahli Muda | E28: 8355 | F28: SESUAI EKSEPEKTASI | G28: BAIK | H28: BAIK | I28: 1
B29: Nip.198304082008011011
A30: 11 | B30: MUKTI FAHDIANSYAH, S.STP | C30: Pembina/IVa | D30: Analis SDM Aparatur Ahli Madya | E30: 8420 | F30: SESUAI EKSEPEKTASI | G30: BAIK | H30: BAIK | I30: 1
B31: Nip.198608032006021001
A32: 12 | B32: KHALIL ACO, S.Sos | C32: Penata Tk.I/IIId | D32: Analis Pengembangan Karir pada Sub Bidang Kepangkatan | E32: 6885 | F32: SESUAI EKSEPEKTASI | G32: BAIK | H32: BAIK | I32: 1
B33: Nip.196912311994031108
A34: 13 | B34: A I D I L, S.Sos | C34: Penata Tk.I/IIId | D34: Pranata Sidik Jari pada Sub Bidang Pembinaan Disiplin dan Kinerja | I34: 0
B35: Nip.196901191996031005
A36: 14 | B36: NASMAH H, SIP | C36: Penata Tk.I/IIId | D36: Analis Sumber Daya Manusia Aparatur Ahli Muda | E36: 7655 | F36: SESUAI EKSEPEKTASI | G36: BAIK | H36: BAIK | I36: 1
B37: Nip.198008142007012008
A38: 15 | B38: A. DWI NUNGRAENI,S.Sos | C38: Penata Tk.I/IIId | D38: Analis Kinerja | E38: 7020 | F38: SESUAI EKSEPEKTASI | G38: BAIK | H38: BAIK | I38: 1
B39: Nip.198407292003122002
A40: 16 | B40: SAHARUNA, S.IP | C40: Penata Tk.I/IIId | D40: Analis Pengembangan Karir | E40: 6820 | F40: SESUAI EKSEPEKTASI | G40: BAIK | H40: BAIK | I40: 1
B41: Nip.198001282007011013
A42: 17 | B42: MURNIATI TOLA, S.IP | C42: Penata/IIIc | D42: Pengelola Kepegawaian | E42: 6770 | F42: SESUAI EKSEPEKTASI | G42: BAIK | H42: BAIK | I42: 1
B43: Nip.197801122008012011
...

Sheet TPP BK
A2: TABEL PERHITUNGAN TPP BEBAN KERJA (BK)
A5: PERANGKAT DAERAH | C5: : BADAN KEPEGAWAIAN PENDIDIKAN DAN PELATIHAN
A6: BULAN | C6: : AGUSTUS 2026
A8: NO | B8: NAMA/NIP | C8: PANGKAT/GOL. RUANG | D8: JABATAN | E8: JUMLAH WKE | F8: JENIS TPP | G8: BPJS 1% | H8: JUMLAH TPP SETELAH POTONGAN BPJS | I8: PREDIKAT KINERJA | L8: DISIPLIN KERJA | O8: JUMLAH TPP KOTOR | P8: PPh 21 | R8: JUMLAH TPP BERSIH | S8: TANDA TANGAN
F9: TPP BK | I9: TPP (60%) | J9: % KINERJA PEGAWAI | K9: JUMLAH | L9: TPP (40%) | M9: PENGURANGAN | N9: JUMLAH
A10: 1 | B10: 2 | C10: 3 | D10: 4 | E10: 5 | F10: 6 | G10: 7(6*1%) | H10: 8(6-7) | I10: 9(8*60%) | J10: 10 | K10: 11(8*9) | L10: 12(8*40%) | M10: 13 | N10: 14(12-13) | O10: 15(11+14) | P10: 16 | R10: 17(15-16) | S10: 18 | U10: agus | V10: Juli
U11: =SUM(O12+G12) -> 1288527 | V11: {=SUM('[1]TPP BK'!$O$12:$O$13+'[1]TPP BK'!$G$12:$G$13)} -> 1288527 | W11: =SUM(U11:V11) -> 2577054
A12: 1 | B12: ANDI HIZBULLAH MASTAR, SKM., M.Kes | C12: Pembina Tk.I/IVb | D12: Kepala BKPSDM | E12: =SUM('PK PNS'!E10:E11) -> 9020 | F12: 1288527 | G12: =SUM(F12*1%) -> 12885.27 | H12: =SUM(F12-G12) -> 1275641.7 | I12: =SUM(H12*60%) -> 765385.04 | J12: =SUM('PK PNS'!I10:I11) -> 1 | K12: =SUM(I12*J12) -> 765385.04 | L12: =SUM(H12*40%) -> 510256.69 | M12: =SUM(L12*Tabel_Perhitungan!AB12) -> 0 | N12: =SUM(L12-M12) -> 510256.69 | O12: =SUM(K12+N12) -> 1275641.7 | P12: 0.15 | Q12: =SUM(O12*P12) -> 191346.26 | R12: =SUM(O12-Q12) -> 1084295.5 | S12: 1 | U12: {=SUM('TPP KK'!O12:O13+'TPP KK'!G12:G13)} -> 453089 | V12: {=SUM('TPP KK'!P12:P13+'TPP KK'!H12:H13)} -> 448558.26 | W12: =SUM(U12:V13) -> 901647.26
B13: Nip.197601072003121007
A14: 2 | B14: Drs. SARIANTO | C14: Pembina Tk.I/IVb | D14: Sekretaris BKPSDM | E14: =SUM('PK PNS'!E12:E13) -> 8460 | F14: 1117734 | G14: =SUM(F14*1%) -> 11177.34 | H14: =SUM(F14-G14) -> 1106556.7 | I14: =SUM(H14*60%) -> 663934 | J14: =SUM('PK PNS'!I12:I13) -> 1 | K14: =SUM(I14*J14) -> 663934 | L14: =SUM(H14*40%) -> 442622.66 | M14: =SUM(L14*Tabel_Perhitungan!AB14) -> 0 | N14: =SUM(L14-M14) -> 442622.66 | O14: =SUM(K14+N14) -> 1106556.7 | P14: 0.15 | Q14: =SUM(O14*P14) -> 165983.5 | R14: =SUM(O14-Q14) -> 940573.16 | S14: 2
B15: Nip.197207051992031005
A16: 3 | B16: MUHAMMAD BAHRUM.S.Sos | C16: Pembina/IVa | D16: Kabid. Amidnistrasi Kepegawaian | E16: =SUM('PK PNS'!E14:E15) -> 8400 | F16: 966432 | G16: =SUM(F16*1%) -> 9664.32 | H16: =SUM(F16-G16) -> 956767.68 | I16: =SUM(H16*60%) -> 574060.61 | J16: =SUM('PK PNS'!I14:I15) -> 1 | K16: =SUM(I16*J16) -> 574060.61 | L16: =SUM(H16*40%) -> 382707.07 | M16: =SUM(L16*Tabel_Perhitungan!AB16) -> 0 | N16: =SUM(L16-M16) -> 382707.07 | O16: =SUM(K16+N16) -> 956767.68 | P16: 0.15 | Q16: =SUM(O16*P16) -> 143515.15 | R16: =SUM(O16-Q16) -> 813252.53 | S16: 3
B17: Nip.198110282000031001
A18: 4 | B18: ZETH DIANTO N.G, S.IP, M.Si | C18: Pembina/IVa | D18: Ka. Bidang Pengadaan, Informasi & Kinerja Pegawai | E18: =SUM('PK PNS'!E16:E17) -> 6870 | F18: 966432 | G18: =SUM(F18*1%) -> 9664.32 | H18: =SUM(F18-G18) -> 956767.68 | I18: =SUM(H18*60%) -> 574060.61 | J18: =SUM('PK PNS'!I16:I17) -> 1 | K18: =SUM(I18*J18) -> 574060.61 | L18: =SUM(H18*40%) -> 382707.07 | M18: =SUM(L18*Tabel_Perhitungan!AB18) -> 0 | N18: =SUM(L18-M18) -> 382707.07 | O18: =SUM(K18+N18) -> 956767.68 | P18: 0.15 | Q18: =SUM(O18*P18) -> 143515.15 | R18: =SUM(O18-Q18) -> 813252.53 | S18: 4
B19: Nip. 197411071993031003
A20: 5 | B20: MUHAMMAD NARWIS, S.STP., MA. | C20: Pembina/IVa | D20: Ka. Bidang Pendidikan & Pelatihan | E20: =SUM('PK PNS'!E18:E19) -> 7643 | F20: 966432 | G20: =SUM(F20*1%) -> 9664.32 | H20: =SUM(F20-G20) -> 956767.68 | I20: =SUM(H20*60%) -> 574060.61 | J20: =SUM('PK PNS'!I18:I19) -> 1 | K20: =SUM(I20*J20) -> 574060.61 | L20: =SUM(H20*40%) -> 382707.07 | M20: =SUM(L20*Tabel_Perhitungan!AB20) -> 0 | N20: =SUM(L20-M20) -> 382707.07 | O20: =SUM(K20+N20) -> 956767.68 | P20: 0.15 | Q20: =SUM(O20*P20) -> 143515.15 | R20: =SUM(O20-Q20) -> 813252.53 | S20: 5
B21: Nip. 198610182006021001
A22: 6 | B22: ANDI SYAMSIAH, SE | C22: Penata Tk.I/IIId | D22: Ka. Sub. Bagian Keuangan, Perencanaan & Pelaporan | E22: =SUM('PK PNS'!E20:E21) -> 7400 | F22: 621537 | G22: =SUM(F22*1%) -> 6215.37 | H22: =SUM(F22-G22) -> 615321.63 | I22: =SUM(H22*60%) -> 369192.98 | J22: =SUM('PK PNS'!I20:I21) -> 1 | K22: =SUM(I22*J22) -> 369192.98 | L22: =SUM(H22*40%) -> 246128.65 | M22: =SUM(L22*Tabel_Perhitungan!AB22) -> 0 | N22: =SUM(L22-M22) -> 246128.65 | O22: =SUM(K22+N22) -> 615321.63 | P22: 0.05 | Q22: =SUM(O22*P22) -> 30766.082 | R22: =SUM(O22-Q22) -> 584555.55 | S22: 6
B23: Nip.197408082006042026
A24: 7 | B24: AKHSAN, S.IP | C24: Penata Tk.I/IIId | D24: Plt. Ka. Sub. Bagian Umum & Kepegawaian | E24: =SUM('PK PNS'!E22:E23) -> 7700 | F24: 499535 | G24: =SUM(F24*1%) -> 4995.35 | H24: =SUM(F24-G24) -> 494539.65 | I24: =SUM(H24*60%) -> 296723.79 | J24: =SUM('PK PNS'!I22:I23) -> 1 | K24: =SUM(I24*J24) -> 296723.79 | L24: =SUM(H24*40%) -> 197815.86 | M24: =SUM(L24*Tabel_Perhitungan!AB24) -> 0 | N24: =SUM(L24-M24) -> 197815.86 | O24: =SUM(K24+N24) -> 494539.65 | P24: 0.05 | Q24: =SUM(O24*P24) -> 24726.983 | R24: =SUM(O24-Q24) -> 469812.67 | S24: 7
B25: Nip.197612312007011093
A26: 8 | B26: R I D W A N, S.Sos | C26: Penata Tk.I/IIId | D26: Analis SDM Aparatur Ahli Madya | E26: =SUM('PK PNS'!E24:E25) -> 7870 | F26: 1117734 | G26: =SUM(F26*1%) -> 11177.34 | H26: =SUM(F26-G26) -> 1106556.7 | I26: =SUM(H26*60%) -> 663934 | J26: =SUM('PK PNS'!I24:I25) -> 1 | K26: =SUM(I26*J26) -> 663934 | L26: =SUM(H26*40%) -> 442622.66 | M26: =SUM(L26*Tabel_Perhitungan!AB26) -> 0 | N26: =SUM(L26-M26) -> 442622.66 | O26: =SUM(K26+N26) -> 1106556.7 | P26: 0.05 | Q26: =SUM(O26*P26) -> 55327.833 | R26: =SUM(O26-Q26) -> 1051228.8 | S26: 8
B27: Nip.196909121994031008
A28: 9 | B28: AMIR SAPIRIHAR, S.Sos | C28: Pembina/IVa | D28: Analis SDM Aparatur Ahli Madya | E28: =SUM('PK PNS'!E26:E27) -> 7025 | F28: 1117734 | G28: =SUM(F28*1%) -> 11177.34 | H28: =SUM(F28-G28) -> 1106556.7 | I28: =SUM(H28*60%) -> 663934 | J28: =SUM('PK PNS'!I26:I27) -> 1 | K28: =SUM(I28*J28) -> 663934 | L28: =SUM(H28*40%) -> 442622.66 | M28: =SUM(L28*Tabel_Perhitungan!AB28) -> 0 | N28: =SUM(L28-M28) -> 442622.66 | O28: =SUM(K28+N28) -> 1106556.7 | P28: 0.15 | Q28: =SUM(O28*P28) -> 165983.5 | R28: =SUM(O28-Q28) -> 940573.16 | S28: 9
B29: Nip.196804242000031013
A30: 10 | B30: ARY ARFAN, SAP, M.Si | C30: Penata Tk.I/IIId | D30: Analis Pengembangan Kompetensi Aparatur Sipil Negara Ahli Muda | E30: =SUM('PK PNS'!E28:E29) -> 8355 | F30: 620474 | G30: =SUM(F30*1%) -> 6204.74 | H30: =SUM(F30-G30) -> 614269.26 | I30: =SUM(H30*60%) -> 368561.56 | J30: =SUM('PK PNS'!I28:I29) -> 1 | K30: =SUM(I30*J30) -> 368561.56 | L30: =SUM(H30*40%) -> 245707.7 | M30: =SUM(L30*Tabel_Perhitungan!AB30) -> 19042.347 | N30: =SUM(L30-M30) -> 226665.36 | O30: =SUM(K30+N30) -> 595226.91 | P30: 0.05 | Q30: =SUM(O30*P30) -> 29761.346 | R30: =SUM(O30-Q30) -> 565465.57 | S30: 10
B31: Nip.198304082008011011
A32: 11 | B32: MUKTI FAHDIANSYAH, S.STP | C32: Pembina/IVa | D32: Analis SDM Aparatur Ahli Madya | E32: =SUM('PK PNS'!E30:E31) -> 8420 | F32: 1117734 | G32: =SUM(F32*1%) -> 11177.34 | H32: =SUM(F32-G32) -> 1106556.7 | I32: =SUM(H32*60%) -> 663934 | J32: =SUM('PK PNS'!I30:I31) -> 1 | K32: =SUM(I32*J32) -> 663934 | L32: =SUM(H32*40%) -> 442622.66 | M32: =SUM(L32*Tabel_Perhitungan!AB32) -> 13278.68 | N32: =SUM(L32-M32) -> 429343.98 | O32: =SUM(K32+N32) -> 1093278 | P32: 0.15 | Q32: =SUM(O32*P32) -> 163991.7 | R32: =SUM(O32-Q32) -> 929286.28 | S32: 11
B33: Nip.198608032006021001
A34: 12 | B34: KHALIL ACO, S.Sos | C34: Penata Tk.I/IIId | D34: Analis Pengembangan Karir pada Sub Bidang Kepangkatan | E34: =SUM('PK PNS'!E32:E33) -> 6885 | F34: 440438 | G34: =SUM(F34*1%) -> 4404.38 | H34: =SUM(F34-G34) -> 436033.62 | I34: =SUM(H34*60%) -> 261620.17 | J34: =SUM('PK PNS'!I32:I33) -> 1 | K34: =SUM(I34*J34) -> 261620.17 | L34: =SUM(H34*40%) -> 174413.45 | M34: =SUM(L34*Tabel_Perhitungan!AB34) -> 9156.706 | N34: =SUM(L34-M34) -> 165256.74 | O34: =SUM(K34+N34) -> 426876.91 | P34: 0.05 | Q34: =SUM(O34*P34) -> 21343.846 | R34: =SUM(O34-Q34) -> 405533.07 | S34: 12
B35: Nip.196912311994031108
A36: 13 | B36: A I D I L, S.Sos | C36: Penata Tk.I/IIId | D36: Pranata Sidik Jari pada Sub Bidang Pembinaan Disiplin dan Kinerja/Anggota PPTK | E36: =SUM('PK PNS'!E34:E35) -> 0 | F36: 0 | G36: =SUM(F36*1%) -> 0 | H36: =SUM(F36-G36) -> 0 | I36: =SUM(H36*60%) -> 0 | J36: =SUM('PK PNS'!I34:I35) -> 0 | K36: =SUM(I36*J36) -> 0 | L36: =SUM(H36*40%) -> 0 | M36: =SUM(L36*Tabel_Perhitungan!AB36) -> 0 | N36: =SUM(L36-M36) -> 0 | O36: =SUM(K36+N36) -> 0 | P36: 0.05 | Q36: =SUM(O36*P36) -> 0 | R36: =SUM(O36-Q36) -> 0 | S36: 13
B37: Nip.196901191996031005
A38: 14 | B38: NASMAH H, SIP | C38: Penata Tk.I/IIId | D38: Analis Sumber Daya Manusia Aparatur Ahli Muda | E38: =SUM('PK PNS'!E36:E37) -> 7655 | F38: 620474 | G38: =SUM(F38*1%) -> 6204.74 | H38: =SUM(F38-G38) -> 614269.26 | I38: =SUM(H38*60%) -> 368561.56 | J38: =SUM('PK PNS'!I36:I37) -> 1 | K38: =SUM(I38*J38) -> 368561.56 | L38: =SUM(H38*40%) -> 245707.7 | M38: =SUM(L38*Tabel_Perhitungan!AB38) -> 7371.2311 | N38: =SUM(L38-M38) -> 238336.47 | O38: =SUM(K38+N38) -> 606898.03 | P38: 0.05 | Q38: =SUM(O38*P38) -> 30344.901 | R38: =SUM(O38-Q38) -> 576553.13 | S38: 14
B39: Nip.198008142007012008
A40: 15 | B40: A. DWI NUNGRAENI,S.Sos | C40: Penata Tk.I/IIId | D40: Analis Kinerja | E40: =SUM('PK PNS'!E38:E39) -> 7020 | F40: 440438 | G40: =SUM(F40*1%) -> 4404.38 | H40: =SUM(F40-G40) -> 436033.62 | I40: =SUM(H40*60%) -> 261620.17 | J40: =SUM('PK PNS'!I38:I39) -> 1 | K40: =SUM(I40*J40) -> 261620.17 | L40: =SUM(H40*40%) -> 174413.45 | M40: =SUM(L40*Tabel_Perhitungan!AB40) -> 17877.378 | N40: =SUM(L40-M40) -> 156536.07 | O40: =SUM(K40+N40) -> 418156.24 | P40: 0.05 | Q40: =SUM(O40*P40) -> 20907.812 | R40: =SUM(O40-Q40) -> 397248.43 | S40: 15
B41: Nip.198407292003122002
A42: 16 | B42: SAHARUNA, S.IP | C42: Penata Tk.I/IIId | D42: Analis Pengembangan Karir | E42: =SUM('PK PNS'!E40:E41) -> 6820 | F42: 440438 | G42: =SUM(F42*1%) -> 4404.38 | H42: =SUM(F42-G42) -> 436033.62 | I42: =SUM(H42*60%) -> 261620.17 | J42: =SUM('PK PNS'!I40:I41) -> 1 | K42: =SUM(I42*J42) -> 261620.17 | L42: =SUM(H42*40%) -> 174413.45 | M42: =SUM(L42*Tabel_Perhitungan!AB42) -> 8720.6724 | N42: =SUM(L42-M42) -> 165692.78 | O42: =SUM(K42+N42) -> 427312.95 | P42: 0.05 | Q42: =SUM(O42*P42) -> 21365.647 | R42: =SUM(O42-Q42) -> 405947.3 | S42: 16
B43: Nip.198001282007011013
A44: 17 | B44: MURNIATI TOLA, S.IP | C44: Penata/IIIc | D44: Pengelola Kepegawaian | E44: =SUM('PK PNS'!E42:E43) -> 6770 | F44: 382735 | G44: =SUM(F44*1%) -> 3827.35 | H44: =SUM(F44-G44) -> 378907.65 | I44: =SUM(H44*60%) -> 227344.59 | J44: =SUM('PK PNS'!I42:I43) -> 1 | K44: =SUM(I44*J44) -> 227344.59 | L44: =SUM(H44*40%) -> 151563.06 | M44: =SUM(L44*Tabel_Perhitungan!AB44) -> 6820.3377 | N44: =SUM(L44-M44) -> 144742.72 | O44: =SUM(K44+N44) -> 372087.31 | P44: 0.05 | Q44: =SUM(O44*P44) -> 18604.366 | R44: =SUM(O44-Q44) -> 353482.95 | S44: 17
...

Sheet TPP KK
A2: TABEL PERHITUNGAN TPP KONDISI KERJA (KK)
A5: PERANGKAT DAERAH | C5: : BADAN KEPEGAWAIAN DAN PENGEMBAGAN SUMBER DAYA MANUSIA
A6: BULAN | C6: : AGUSTUS 2026
A8: NO | B8: NAMA/NIP | C8: PANGKAT/GOL. RUANG | D8: JABATAN | E8: JUMLAH WKE | F8: JENIS TPP | G8: BPJS 1% | H8: JUMLAH TPP SETELAH POTONGAN BPJS | I8: PREDIKAT KINERJA | L8: DISIPLIN KERJA | O8: JUMLAH TPP KOTOR | P8: PPh 21 | R8: JUMLAH TPP BERSIH | S8: TANDA TANGAN
F9: TPP KK | I9: TPP (60%) | J9: % KINERJA PEGAWAI | K9: JUMLAH | L9: TPP (40%) | M9: PENGURANGAN | N9: JUMLAH
A10: 1 | B10: 2 | C10: 3 | D10: 4 | E10: 5 | F10: 6 | G10: 7(6*1%) | H10: 8(6-7) | I10: 9(8*60%) | J10: 10 | K10: 11(8*9) | L10: 12(8*40%) | M10: 13 | N10: 14(12-13) | O10: 15(11+14) | P10: 16 | R10: 17(15-16) | S10: 18
A12: 1 | B12: ANDI HIZBULLAH MASTAR, SKM., M.Kes | C12: Pembina Tk.I/IVb | D12: Kepala BKPSDM | E12: =SUM('PK PNS'!E10:E11) -> 9020 | F12: 453089 | G12: =SUM(F12*1%) -> 4530.89 | H12: =SUM(F12-G12) -> 448558.11 | I12: =SUM(H12*60%) -> 269134.87 | J12: =SUM('PK PNS'!I10:I11) -> 1 | K12: =SUM(I12*J12) -> 269134.87 | L12: =SUM(H12*40%) -> 179423.24 | M12: =SUM(L12*Tabel_Perhitungan!AB12) -> 0 | N12: =SUM(L12-M12) -> 179423.24 | O12: =SUM(K12+N12) -> 448558.11 | P12: 0.15 | Q12: =SUM(O12*P12) -> 67283.716 | R12: =SUM(O12-Q12) -> 381274.39 | S12: 1
B13: Nip.197601072003121007
B16: JUMLAH | F16: =SUM(F12:F15) -> 453089 | G16: =SUM(G12:G13) -> 4530.89 | H16: =SUM(H12:H13) -> 448558.11 | I16: =SUM(I12:I13) -> 269134.87 | K16: =SUM(K12:K13) -> 269134.87 | L16: =SUM(L12:L13) -> 179423.24 | M16: =SUM(M12:M13) -> 0 | N16: =SUM(N12:N13) -> 179423.24 | O16: =SUM(O12:O13) -> 448558.11 | P16: =SUM(Q12:Q13) -> 67283.716 | R16: =SUM(R12:R13) -> 381274.39
O19: Polewali, 28 September 2026
O21: KEPALA BADAN KEPEGAWAIAN DAN
O22: PENGEMBANGAN SUMBER DAYA MANUSIA
O26: ANDI HIZBULLAH MASTAR, SKM., M.Kes
O27: Pangkat | P27: : Pembina Tk.I
O28: NIP. | P28: : 197601072003121007
U51: Jumlah Kotor | V51: BPJS | W51: Jumlah Kotor + BPJS | X51: PPH 21 | Y51: Jml Kotor-PPh 21

Sheet TPP REKAP BK&KK
A2: TABEL PERHITUNGAN TPP BEBAN KERJA DAN KONDISI KERJA (BK & KK)
A5: PERANGKAT DAERAH | C5: : BADAN KEPEGAWAIAN DAN PENGEMBAGAN SUMBER DAYA MANUSIA
A6: BULAN | C6: : AGUSTUS 2026
A8: NO | B8: NAMA/NIP | C8: PANGKAT/GOL. RUANG | D8: JABATAN | E8: JUMLAH WKE | F8: JENIS TPP | H8: JUMLAH TPP | I8: BPJS 1% | J8: JUMLAH TPP SETELAH POTONGAN BPJS | K8: PREDIKAT KINERJA | N8: DISIPLIN KERJA | Q8: JUMLAH TPP KOTOR | R8: PPh 21 | T8: JUMLAH TPP BERSIH | U8: TANDA TANGAN
F9: TPP BK | G9: TPP KK | K9: TPP (60%) | L9: % KINERJA PEGAWAI | M9: JUMLAH | N9: TPP (40%) | O9: PENGURANGAN | P9: JUMLAH
A10: 1 | B10: 2 | C10: 3 | D10: 4 | E10: 5 | F10: 6 | G10: 8 | H10: 9 (6+8) | I10: 10(9*1%) | J10: 11(9-10) | K10: 12(11*60%) | L10: 13 | M10: 14(12*13) | N10: 15(11*40%) | O10: 16 | P10: 17(15-16) | Q10: 18(12+17) | R10: 19(18*19) | T10: 20(18-19) | U10: 21
A12: 1 | B12: ANDI HIZBULLAH MASTAR, SKM., M.Kes | C12: Pembina Tk.I/IVb | D12: Kepala BKPSDM | E12: =SUM('PK PNS'!E10:E11) -> 9020 | F12: 1288527 | G12: 453089 | H12: =SUM(F12:G13) -> 1741616 | I12: =SUM(H12*1%) -> 17416.16 | J12: =SUM(H12-I12) -> 1724199.8 | K12: =SUM(J12*60%) -> 1034519.9 | L12: =SUM('PK PNS'!I10:I11) -> 1 | M12: =SUM(K12*L12) -> 1034519.9 | N12: =SUM(J12*40%) -> 689679.94 | O12: =SUM(N12*Tabel_Perhitungan!AB12) -> 0 | P12: =SUM(N12-O12) -> 689679.94 | Q12: =SUM(M12+P12) -> 1724199.8 | R12: 0.15 | S12: =SUM(Q12*R12) -> 258629.98 | T12: =SUM(Q12-S12) -> 1465569.9 | U12: 1 | W12: 17416.16 | X12: 1724199.8 | Y12: =SUM(S12) -> 258629.98
B13: Nip.197601072003121007 | W13: 11177.34 | X13: 1106556.7 | Y13: =SUM(S14) -> 165983.5
A14: 2 | B14: Drs. SARIANTO | C14: Pembina Tk.I/IVb | D14: Sekretaris BKPSDM | E14: =SUM('PK PNS'!E12:E13) -> 8460 | F14: 1117734 | G14: 0 | H14: =SUM(F14:G15) -> 1117734 | I14: =SUM(H14*1%) -> 11177.34 | J14: =SUM(H14-I14) -> 1106556.7 | K14: =SUM(J14*60%) -> 663934 | L14: =SUM('PK PNS'!I12:I13) -> 1 | M14: =SUM(K14*L14) -> 663934 | N14: =SUM(J14*40%) -> 442622.66 | O14: =SUM(N14*Tabel_Perhitungan!AB14) -> 0 | P14: =SUM(N14-O14) -> 442622.66 | Q14: =SUM(M14+P14) -> 1106556.7 | R14: 0.15 | S14: =SUM(Q14*R14) -> 165983.5 | T14: =SUM(Q14-S14) -> 940573.16 | U14: 2 | W14: 9664.32 | X14: 956767.68
B15: Nip.197207051992031005 | W15: 9664.32 | X15: 956767.68
A16: 3 | B16: MUHAMMAD BAHRUM.S.Sos | C16: Pembina/IVa | D16: Kabid. Amidnistrasi Kepegawaian | E16: =SUM('PK PNS'!E14:E15) -> 8400 | F16: 966432 | G16: 0 | H16: =SUM(F16:G17) -> 966432 | I16: =SUM(H16*1%) -> 9664.32 | J16: =SUM(H16-I16) -> 956767.68 | K16: =SUM(J16*60%) -> 574060.61 | L16: =SUM('PK PNS'!I14:I15) -> 1 | M16: =SUM(K16*L16) -> 574060.61 | N16: =SUM(J16*40%) -> 382707.07 | O16: =SUM(N16*Tabel_Perhitungan!AB16) -> 0 | P16: =SUM(N16-O16) -> 382707.07 | Q16: =SUM(M16+P16) -> 956767.68 | R16: 0.15 | S16: =SUM(Q16*R16) -> 143515.15 | T16: =SUM(Q16-S16) -> 813252.53 | U16: 3 | W16: 9664.32 | X16: 956767.68
B17: Nip.198110282000031001 | W17: 6215.37 | X17: 615321.63
A18: 4 | B18: ZETH DIANTO N.G, S.IP, M.Si | C18: Pembina/IVa | D18: Ka. Bidang Pengadaan, Informasi & Kinerja Pegawai | E18: =SUM('PK PNS'!E16:E17) -> 6870 | F18: 966432 | G18: 0 | H18: =SUM(F18:G19) -> 966432 | I18: =SUM(H18*1%) -> 9664.32 | J18: =SUM(H18-I18) -> 956767.68 | K18: =SUM(J18*60%) -> 574060.61 | L18: =SUM('PK PNS'!I16:I17) -> 1 | M18: =SUM(K18*L18) -> 574060.61 | N18: =SUM(J18*40%) -> 382707.07 | O18: =SUM(N18*Tabel_Perhitungan!AB18) -> 0 | P18: =SUM(N18-O18) -> 382707.07 | Q18: =SUM(M18+P18) -> 956767.68 | R18: 0.15 | S18: =SUM(Q18*R18) -> 143515.15 | T18: =SUM(Q18-S18) -> 813252.53 | U18: 4 | W18: 4995.35 | X18: 494539.65
B19: Nip. 197411071993031003 | W19: 11177.34 | X19: 1106556.7
A20: 5 | B20: MUHAMMAD NARWIS, S.STP., MA. | C20: Pembina/IVa | D20: Ka. Bidang Pendidikan & Pelatihan | E20: =SUM('PK PNS'!E18:E19) -> 7643 | F20: 966432 | G20: 0 | H20: =SUM(F20:G21) -> 966432 | I20: =SUM(H20*1%) -> 9664.32 | J20: =SUM(H20-I20) -> 956767.68 | K20: =SUM(J20*60%) -> 574060.61 | L20: =SUM('PK PNS'!I18:I19) -> 1 | M20: =SUM(K20*L20) -> 574060.61 | N20: =SUM(J20*40%) -> 382707.07 | O20: =SUM(N20*Tabel_Perhitungan!AB20) -> 0 | P20: =SUM(N20-O20) -> 382707.07 | Q20: =SUM(M20+P20) -> 956767.68 | R20: 0.15 | S20: =SUM(Q20*R20) -> 143515.15 | T20: =SUM(Q20-S20) -> 813252.53 | U20: 5 | W20: 11177.34 | X20: 1106556.7
B21: Nip. 198610182006021001 | W21: 6204.74 | X21: 595226.91
A22: 6 | B22: ANDI SYAMSIAH, SE | C22: Penata Tk.I/IIId | D22: Ka. Sub. Bagian Keuangan, Perencanaan & Pelaporan | E22: =SUM('PK PNS'!E20:E21) -> 7400 | F22: 621537 | G22: 0 | H22: =SUM(F22:G23) -> 621537 | I22: =SUM(H22*1%) -> 6215.37 | J22: =SUM(H22-I22) -> 615321.63 | K22: =SUM(J22*60%) -> 369192.98 | L22: =SUM('PK PNS'!I20:I21) -> 1 | M22: =SUM(K22*L22) -> 369192.98 | N22: =SUM(J22*40%) -> 246128.65 | O22: =SUM(N22*Tabel_Perhitungan!AB22) -> 0 | P22: =SUM(N22-O22) -> 246128.65 | Q22: =SUM(M22+P22) -> 615321.63 | R22: 0.05 | S22: =SUM(Q22*R22) -> 30766.082 | T22: =SUM(Q22-S22) -> 584555.55 | U22: 6 | W22: 11177.34 | X22: 1093278
B23: Nip.197408082006042026 | W23: 4404.38 | X23: 426876.91
A24: 7 | B24: AKHSAN, S.IP | C24: Penata Tk.I/IIId | D24: Plt. Ka. Sub. Bagian Umum & Kepegawaian | E24: =SUM('PK PNS'!E22:E23) -> 7700 | F24: 499535 | G24: 0 | H24: =SUM(F24:G25) -> 499535 | I24: =SUM(H24*1%) -> 4995.35 | J24: =SUM(H24-I24) -> 494539.65 | K24: =SUM(J24*60%) -> 296723.79 | L24: =SUM('PK PNS'!I22:I23) -> 1 | M24: =SUM(K24*L24) -> 296723.79 | N24: =SUM(J24*40%) -> 197815.86 | O24: =SUM(N24*Tabel_Perhitungan!AB24) -> 0 | P24: =SUM(N24-O24) -> 197815.86 | Q24: =SUM(M24+P24) -> 494539.65 | R24: 0.05 | S24: =SUM(Q24*R24) -> 24726.983 | T24: =SUM(Q24-S24) -> 469812.67 | U24: 7 | W24: 0 | X24: 0
B25: Nip.197612312007011093 | W25: 6204.74 | X25: 606898.03
A26: 8 | B26: R I D W A N, S.Sos | C26: Penata Tk.I/IIId | D26: Analis SDM Aparatur Ahli Madya | E26: =SUM('PK PNS'!E24:E25) -> 7870 | F26: 1117734 | G26: 0 | H26: =SUM(F26:G27) -> 1117734 | I26: =SUM(H26*1%) -> 11177.34 | J26: =SUM(H26-I26) -> 1106556.7 | K26: =SUM(J26*60%) -> 663934 | L26: =SUM('PK PNS'!I24:I25) -> 1 | M26: =SUM(K26*L26) -> 663934 | N26: =SUM(J26*40%) -> 442622.66 | O26: =SUM(N26*Tabel_Perhitungan!AB26) -> 0 | P26: =SUM(N26-O26) -> 442622.66 | Q26: =SUM(M26+P26) -> 1106556.7 | R26: 0.05 | S26: =SUM(Q26*R26) -> 55327.833 | T26: =SUM(Q26-S26) -> 1051228.8 | U26: 8 | W26: 4404.38 | X26: 418156.24
B27: Nip.196909121994031008 | W27: 4404.38 | X27: 427312.95
A28: 9 | B28: AMIR SAPIRIHAR, S.Sos | C28: Pembina/IVa | D28: Analis SDM Aparatur Ahli Madya | E28: =SUM('PK PNS'!E26:E27) -> 7025 | F28: 1117734 | G28: 0 | H28: =SUM(F28:G29) -> 1117734 | I28: =SUM(H28*1%) -> 11177.34 | J28: =SUM(H28-I28) -> 1106556.7 | K28: =SUM(J28*60%) -> 663934 | L28: =SUM('PK PNS'!I26:I27) -> 1 | M28: =SUM(K28*L28) -> 663934 | N28: =SUM(J28*40%) -> 442622.66 | O28: =SUM(N28*Tabel_Perhitungan!AB28) -> 0 | P28: =SUM(N28-O28) -> 442622.66 | Q28: =SUM(M28+P28) -> 1106556.7 | R28: 0.15 | S28: =SUM(Q28*R28) -> 165983.5 | T28: =SUM(Q28-S28) -> 940573.16 | U28: 9 | W28: 3827.35 | X28: 372087.31
B29: Nip.196804242000031013 | W29: 4995.35 | X29: 482670.7
A30: 10 | B30: ARY ARFAN, SAP, M.Si | C30: Penata Tk.I/IIId | D30: Analis Pengembangan Kompetensi Aparatur Sipil Negara Ahli Muda | E30: =SUM('PK PNS'!E28:E29) -> 8355 | F30: 620474 | G30: 0 | H30: =SUM(F30:G31) -> 620474 | I30: =SUM(H30*1%) -> 6204.74 | J30: =SUM(H30-I30) -> 614269.26 | K30: =SUM(J30*60%) -> 368561.56 | L30: =SUM('PK PNS'!I28:I29) -> 1 | M30: =SUM(K30*L30) -> 368561.56 | N30: =SUM(J30*40%) -> 245707.7 | O30: =SUM(N30*Tabel_Perhitungan!AB30) -> 19042.347 | P30: =SUM(N30-O30) -> 226665.36 | Q30: =SUM(M30+P30) -> 595226.91 | R30: 0.05 | S30: =SUM(Q30*R30) -> 29761.346 | T30: =SUM(Q30-S30) -> 565465.57 | U30: 10 | W30: 3192.02 | X30: 299577.46
B31: Nip.198304082008011011 | W31: 4404.38 | X31: 436033.62
A32: 11 | B32: MUKTI FAHDIANSYAH, S.STP | C32: Pembina/IVa | D32: Analis SDM Aparatur Ahli Madya | E32: =SUM('PK PNS'!E30:E31) -> 8420 | F32: 1117734 | G32: 0 | H32: =SUM(F32:G33) -> 1117734 | I32: =SUM(H32*1%) -> 11177.34 | J32: =SUM(H32-I32) -> 1106556.7 | K32: =SUM(J32*60%) -> 663934 | L32: =SUM('PK PNS'!I30:I31) -> 1 | M32: =SUM(K32*L32) -> 663934 | N32: =SUM(J32*40%) -> 442622.66 | O32: =SUM(N32*Tabel_Perhitungan!AB32) -> 13278.68 | P32: =SUM(N32-O32) -> 429343.98 | Q32: =SUM(M32+P32) -> 1093278 | R32: 0.15 | S32: =SUM(Q32*R32) -> 163991.7 | T32: =SUM(Q32-S32) -> 929286.28 | U32: 11 | W32: 3827.35 | X32: 378907.65
B33: Nip.198608032006021001 | W33: 3827.35 | X33: 374360.76
A34: 12 | B34: KHALIL ACO, S.Sos | C34: Penata Tk.I/IIId | D34: Analis Pengembangan Karir pada Sub Bidang Kepangkatan | E34: =SUM('PK PNS'!E32:E33) -> 6885 | F34: 440438 | G34: 0 | H34: =SUM(F34:G35) -> 440438 | I34: =SUM(H34*1%) -> 4404.38 | J34: =SUM(H34-I34) -> 436033.62 | K34: =SUM(J34*60%) -> 261620.17 | L34: =SUM('PK PNS'!I32:I33) -> 1 | M34: =SUM(K34*L34) -> 261620.17 | N34: =SUM(J34*40%) -> 174413.45 | O34: =SUM(N34*Tabel_Perhitungan!AB34) -> 9156.706 | P34: =SUM(N34-O34) -> 165256.74 | Q34: =SUM(M34+P34) -> 426876.91 | R34: 0.05 | S34: =SUM(Q34*R34) -> 21343.846 | T34: =SUM(Q34-S34) -> 405533.07 | U34: 12 | W34: 3827.35 | X34: 369813.87
B35: Nip.196912311994031108 | W35: 4404.38 | X35: 436033.62
A36: 13 | B36: A I D I L, S.Sos | C36: Penata Tk.I/IIId | D36: Pranata Sidik Jari pada Sub Bidang Pembinaan Disiplin dan Kinerja/Anggota PPTK | E36: =SUM('PK PNS'!E34:E35) -> 0 | F36: 0 | G36: 0 | H36: =SUM(F36:G37) -> 0 | I36: =SUM(H36*1%) -> 0 | J36: =SUM(H36-I36) -> 0 | K36: =SUM(J36*60%) -> 0 | L36: =SUM('PK PNS'!I34:I35) -> 0 | M36: =SUM(K36*L36) -> 0 | N36: =SUM(J36*40%) -> 0 | O36: =SUM(N36*Tabel_Perhitungan!AB36) -> 0 | P36: =SUM(N36-O36) -> 0 | Q36: =SUM(M36+P36) -> 0 | R36: 0.05 | S36: =SUM(Q36*R36) -> 0 | T36: =SUM(Q36-S36) -> 0 | U36: 13 | W36: 6204.74 | X36: 614269.26
B37: Nip.196901191996031005 | W37: 6204.74 | X37: 584784.34
A38: 14 | B38: NASMAH H, SIP | C38: Penata Tk.I/IIId | D38: Analis Sumber Daya Manusia Aparatur Ahli Muda | E38: =SUM('PK PNS'!E36:E37) -> 7655 | F38: 620474 | G38: 0 | H38: =SUM(F38:G39) -> 620474 | I38: =SUM(H38*1%) -> 6204.74 | J38: =SUM(H38-I38) -> 614269.26 | K38: =SUM(J38*60%) -> 368561.56 | L38: =SUM('PK PNS'!I36:I37) -> 1 | M38: =SUM(K38*L38) -> 368561.56 | N38: =SUM(J38*40%) -> 245707.7 | O38: =SUM(N38*Tabel_Perhitungan!AB38) -> 7371.2311 | P38: =SUM(N38-O38) -> 238336.47 | Q38: =SUM(M38+P38) -> 606898.03 | R38: 0.05 | S38: =SUM(Q38*R38) -> 30344.901 | T38: =SUM(Q38-S38) -> 576553.13 | U38: 14 | W38: 4995.35 | X38: 491572.41
B39: Nip.198008142007012008 | W39: 4995.35 | X39: 476736.22
A40: 15 | B40: A. DWI NUNGRAENI,S.Sos | C40: Penata Tk.I/IIId | D40: Analis Kinerja | E40: =SUM('PK PNS'!E38:E39) -> 7020 | F40: 440438 | G40: 0 | H40: =SUM(F40:G41) -> 440438 | I40: =SUM(H40*1%) -> 4404.38 | J40: =SUM(H40-I40) -> 436033.62 | K40: =SUM(J40*60%) -> 261620.17 | L40: =SUM('PK PNS'!I38:I39) -> 1 | M40: =SUM(K40*L40) -> 261620.17 | N40: =SUM(J40*40%) -> 174413.45 | O40: =SUM(N40*Tabel_Perhitungan!AB40) -> 17877.378 | P40: =SUM(N40-O40) -> 156536.07 | Q40: =SUM(M40+P40) -> 418156.24 | R40: 0.05 | S40: =SUM(Q40*R40) -> 20907.812 | T40: =SUM(Q40-S40) -> 397248.43 | U40: 15 | W40: 6204.74 | X40: 614269.26
B41: Nip.198407292003122002 | W41: 4404.38 | X41: 420336.41
A42: 16 | B42: SAHARUNA, S.IP | C42: Penata Tk.I/IIId | D42: Analis Pengembangan Karir | E42: =SUM('PK PNS'!E40:E41) -> 6820 | F42: 440438 | G42: 0 | H42: =SUM(F42:G43) -> 440438 | I42: =SUM(H42*1%) -> 4404.38 | J42: =SUM(H42-I42) -> 436033.62 | K42: =SUM(J42*60%) -> 261620.17 | L42: =SUM('PK PNS'!I40:I41) -> 1 | M42: =SUM(K42*L42) -> 261620.17 | N42: =SUM(J42*40%) -> 174413.45 | O42: =SUM(N42*Tabel_Perhitungan!AB42) -> 8720.6724 | P42: =SUM(N42-O42) -> 165692.78 | Q42: =SUM(M42+P42) -> 427312.95 | R42: 0.05 | S42: =SUM(Q42*R42) -> 21365.647 | T42: =SUM(Q42-S42) -> 405947.3 | U42: 16 | W42: 3827.35 | X42: 378907.65
B43: Nip.198001282007011013 | W43: 4995.35 | X43: 494539.65
A44: 17 | B44: MURNIATI TOLA, S.IP | C44: Penata/IIIc | D44: Pengelola Kepegawaian | E44: =SUM('PK PNS'!E42:E43) -> 6770 | F44: 382735 | G44: 0 | H44: =SUM(F44:G45) -> 382735 | I44: =SUM(H44*1%) -> 3827.35 | J44: =SUM(H44-I44) -> 378907.65 | K44: =SUM(J44*60%) -> 227344.59 | L44: =SUM('PK PNS'!I42:I43) -> 1 | M44: =SUM(K44*L44) -> 227344.59 | N44: =SUM(J44*40%) -> 151563.06 | O44: =SUM(N44*Tabel_Perhitungan!AB44) -> 6820.3377 | P44: =SUM(N44-O44) -> 144742.72 | Q44: =SUM(M44+P44) -> 372087.31 | R44: 0.05 | S44: =SUM(Q44*R44) -> 18604.366 | T44: =SUM(Q44-S44) -> 353482.95 | U44: 17 | W44: 4404.38 | X44: 435161.55
B45: Nip.197801122008012011 | W45: 3827.35 | X45: 378907.65
...

Sheet Sheet1

Sheet REKENING
A2: DAFTAR TPP BADAN KEPEGAWAIAN PENDIDIKAN DAN PELATIHAN (BKPP)
A3: BULAN JANUARI 2025
A6: NO | B6: NIP | C6: NAMA | D6: NOMOR HP | E6: No. REKENING | F6: JUMLAH TPP BULAN APRIL 2025
A8: 1 | B8: 2 | C8: 3 | D8: 4 | E8: 5 | F8: 6
A9: 1 | B9: 196605201992031017 | C9: Ir. BUDI UTOMO ABDULLAH, MM | D9: 081342082622 | E9: 070-201-0000222031 | F9: =SUM('[4]TPP BK'!Q11) -> 293176.08
A11: 2 | B11: 197207051992031005 | C11: Drs. SARIANTO | D11: 085242627674 | E11: 070-201-0000110446 | F11: =SUM('[4]TPP BK'!Q13) -> 943949.79
A13: 3 | B13: 197308031994021002 | C13: ANDI ILHAM JAYA, S.So, M.M | D13: 085272522555 | E13: 070-201-000121677 | F13: =SUM('[4]TPP BK'!Q15) -> 780989.58
A15: 4 | B15: 198110282000031001 | C15: MUHAMMAD BAHRUM.S.Sos | D15: 085298878878 | E15: 070-201-0000122916 | F15: =SUM('[4]TPP BK'!Q19) -> 798679.26
A17: 5 | B17: 197612312007011093 | C17: AKHSAN, S.IP | D17: 081342586632 | E17: 070-201-0000129287 | F17: =SUM('[4]TPP BK'!Q21) -> 454393.43
A19: 6 | B19: 196909121994031008 | C19: R I D W A N, S.Sos | D19: 085255287100 | E19: 070-201-0000122932 | F19: =SUM('[4]TPP BK'!Q23) -> 649909.89
A21: 7 | B21: 197408082006042026 | C21: ANDI SYAMSIAH, SE | D21: 085255533299 | E21: 070-201-0000122258 | F21: =SUM('[4]TPP BK'!Q25) -> 581135.16
A23: 8 | B23: 196804242000031013 | C23: AMIR SAPIRIHAR, S.Sos | D23: 085340978555 | E23: 070-201-000012084-1 | F23: =SUM('[4]TPP BK'!Q27) -> 668056.29
A25: 9 | B25: 198304082008011011 | C25: ARY ARFAN, SAP, M.Si | D25: 085242003007 | E25: 070-201-0000115634 | F25: =SUM('[4]TPP BK'!Q29) -> 643861.09
A27: 10 | B27: 198608032006021001 | C27: MUKTI FAHDIANSYAH, S.STP | D27: 082188992121 | E27: 070-201-000012598-2 | F27: =SUM('[4]TPP BK'!Q31) -> 587541.82
A29: 11 | B29: 196912311994031108 | C29: KHALIL ACO, S.Sos | D29: 082188990809 | E29: 070-201-0000123700 | F29: =SUM('[4]TPP BK'!Q33) -> 390693.44
A31: 12 | B31: 198008142007012008 | C31: A I D I L, S.Sos | D31: 082347034533 | E31: 070-201-0000148290 | F31: =SUM('[4]TPP BK'!Q35) -> 342748.54
A33: 13 | B33: 198407292003122002 | C33: NASMAH H, SIP | D33: 081355884180 | E33: 070-201-0000122576 | F33: =SUM('[4]TPP BK'!Q37) -> 349121.07
A35: 14 | B35: 198407292003122002 | C35: A. DWI NUNGRAENI,S.Sos | D35: 085242229872 | E35: 070-201-0000123122 | F35: =SUM('[4]TPP BK'!Q39) -> 383546.61
A37: 15 | B37: 198001282007011013 | C37: SAHARUNA, S.IP | D37: 082349514715 | E37: 070-201-0000113615 | F37: =SUM('[4]TPP BK'!Q41) -> 399393.93
... A49: 21 | B49: 198008182009011015 | C49: MAQFUR SALEH, A.Md. Kom | D49: 081343919140 | E49: 070-201-0000122550 | F49: =SUM('[4]TPP BK'!Q53) -> 340318.34
A51: 22 | B51: 197805032009011006 | C51: RUSMAN RUBAMA | E51: 070-201-0000137948 | F51: =SUM('[4]TPP BK'!Q55) -> 351067.13
A53: 23 | B53: 198908082010011001 | C53: MUHAMMAD AKBAR, S.IP | D53: 085255660006 | E53: 070-201-0000150421 | F53: =SUM('[4]TPP BK'!Q57) -> 404303.5
A55: 24 | B55: 198407012014121003 | C55: ZULKIFLI, SH | D55: 085255543900 | E55: 070-201-0000186841 | F55: =SUM('[4]TPP BK'!Q59) -> 345988.81
A57: 25 | B57: 198010062011011003 | C57: ABDUL RAHMAN MADJID, S.Kom | D57: 081340219899 | E57: 070-201-0000158457 | F57: =SUM('[4]TPP BK'!Q61) -> 387275.39
A59: 26 | B59: 198010062011011003 | C59: MUNAWIR | D59: 081384378870 | E59: 070-201-0000185730 | F59: =SUM('[4]TPP BK'!Q63) -> 392868.57
A61: 27 | B61: 198602062009041001 | C61: HARIAWAN SAPUTRA, A.Md | D61: 081257926188 | E61: 072-201-0000072152 | F61: =SUM('[4]TPP BK'!Q65) -> 347608.95
A63: 28 | B63: 198501042010011014 | C63: MUH. ADE DJAFAR, S.Kom | D63: 081342055890 | E63: 073-201-0000049589 | F63: =SUM('[4]TPP BK'!Q67) -> 413687.6
A65: 29 | B65: 198511012014121001 | C65: AHMAD DZULKARNAIN, S.Kom | D65: 085156766369 | E65: 070-201-0000185748 | F65: =SUM('[4]TPP BK'!Q69) -> 378264.17
A67: 30 | B67: 199202282011012001 | C67: WAHYUNI, S.IP | D67: 085247225136 | E67: 070-201-0000158104 | F67: =SUM('[4]TPP BK'!Q71) -> 357329.76
A69: 31 | B69: 198012292006042011 | C69: INDRIYANI, A.Md | D69: 085255701659 | E69: 70-201-0000151304 | F69: =SUM('[4]TPP BK'!Q73) -> 353549.44
A71: 32 | B71: 198308112009011004 | C71: SYAFARUDDIN, S.Sos | D71: 081242260550 | E71: 070-201-0000198815 | F71: =SUM('[4]TPP BK'!Q75) -> 406789.35
A73: 33 | B73: 198511112015031002 | C73: MUH. SAHAL HALIM, S.Kom | D73: 085341108729 | E73: 070-201-0000236423 | F73: =SUM('[4]TPP BK'!Q77) -> 356519.69
A75: 34 | B75: 199004242022022001 | C75: FITRIA ULFA MAKMUR, S.E | D75: 082346745900 | E75: 070-201-0000235052 | F75: =SUM('[4]TPP BK'!Q79) -> 411823.21
... A89: 41 | B89: 200109302023082001 | C89: SHALSHA ANUGRAH RAHMAN, S.Tr.I.P | D89: 085258185988 | E89: 206-201-0000018334 | F89: =SUM('[4]TPP BK'!Q93) -> 409337.35
B91: JUMLAH | F91: =SUM(F9:F90) -> 17813081
A92: Hp | B92: : 085341727060 (Pengelola Gaji)
D95: Polewali, Agustus 2025
D97: KEPALA BADAN KEPEGAWAIAN
D98: PENDIDIKAN DAN PELATIHAN
D102: Ir. BUDI UTOMO ABDULLAH, MM
...

Sheet Sheet4

Sheet Sheet2
C6: DAFTAR TPP BKPP | H6: DAFTAR TPP BKPP
C7: BULAN DESEMBER 2021 | H7: BULAN MARET 2022
C8: TAHUN ANGGARAN 2022 | H8: TAHUN ANGGARAN 2022
C12: DAFTAR TPP BKPP | H12: DAFTAR TPP BKPP | O12: 2,511,500 | P12: =SUM(O12*2%) -> #VALUE!
C13: BULAN JANUARI 2022 | H13: BULAN APRIL 2022
C14: TAHUN ANGGARAN 2022 | H14: TAHUN ANGGARAN 2022
C18: DAFTAR TPP BKPP | H18: DAFTAR TPP BKPP
C19: BULAN FEBRUARI 2022 | H19: BULAN MEI 2022
C20: TAHUN ANGGARAN 2022 | H20: TAHUN ANGGARAN 2022

Sheet Sheet3
A1: NO | B1: Jabatan | C1: Jenis Jabatan | D1: Kelas jabatan | E1: Bulan | F1: Jumlah pemangku | G1: beban kerja/Bln | H1: beban kerja/12 BLN
A3: 1 | C3: 2 | E3: 4 | F3: 5 | G3: 6 | H3: 7(6*1%)
B5: Ka.Badan BKPSDM | C5: Pimpinan Tinggi | D5: 14 | E5: 12 | F5: 1 | G5: 1288527 | H5: =SUM(G5*F5*E5) -> 15462324
A6: 1 | B6: Sekretris Badan | C6: Administrator | D6: 12 | E6: 6 | F6: 1 | G6: 1117734 | H6: =SUM(G6*F6*E6) -> 6706404
A7: 2 | B7: Ka. Bidang | C7: Administrator | D7: 11 | E7: 12 | F7: 3 | G7: 966432 | H7: =SUM(G7*F7*E7) -> 34791552
B8: Ka. Sub. Bagian Keuangan, Perencanaan & Pelaporan | C8: Pengawas | D8: 9 | E8: 12 | F8: 1 | G8: 621537 | H8: =SUM(G8*F8*E8) -> 7458444
B9: Ka. Sub. Bagian Umum & Kepegawaian | C9: Pengawas | D9: 8 | E9: 12 | F9: 1 | G9: 499537 | H9: =SUM(G9*F9*E9) -> 5994444
B10: Analis SDM Aparatur Ahli Madya | C10: Fungsional | D10: 12 | E10: 12 | F10: 1 | G10: 1117734 | H10: =SUM(G10*F10*E10) -> 13412808
B11: Analis SDM Aparatur Ahli Muda | C11: Fungsional | D11: 10 | E11: 4 | F11: 2 | G11: 620474 | H11: =SUM(G11*F11*E11) -> 4963792
B12: Analis SDM Aparatur Ahli Madya | C12: Fungsional | D12: 12 | E12: 8 | F12: 2 | G12: 1117734 | H12: =SUM(G12*F12*E12) -> 17883744
B13: Sekretariat BKPP | C13: Pelaksana | D13: 6 | E13: 12 | F13: 4 | G13: 382735 | H13: =SUM(G13*F13*E13) -> 18371280
C14: Pelaksana | D14: 5 | E14: 12 | F14: 1 | G14: 319202 | H14: =SUM(G14*F14*E14) -> 3830424
B15: Sub. Bagian Keuangan | C15: Pelaksana | D15: 7 | E15: 12 | F15: 2 | G15: 440438 | H15: =SUM(G15*F15*E15) -> 10570512 | I15: Akbar/Pera
C16: Pelaksana | D16: 7 | E16: 4 | F16: 1 | G16: 440438 | H16: =SUM(G16*F16*E16) -> 1761752 | I16: Fitri
B17: Analis SDM Aparatur Ahli Pertama | C17: Fungsional | D17: 8 | E17: 8 | F17: 1 | G17: 499535 | H17: =SUM(G17*F17*E17) -> 3996280
C18: Pelaksana | D18: 6 | E18: 4 | F18: 1 | G18: 382735 | H18: =SUM(G18*F18*E18) -> 1530940 | I18: Zul
B19: Analis SDM Aparatur Ahli Muda | C19: Fungsional | D19: 10 | E19: 8 | F19: 1 | G19: 620474 | H19: =SUM(G19*F19*E19) -> 4963792
C20: Pelaksana | D20: 6 | E20: 4 | F20: 1 | G20: 382735 | H20: =SUM(G20*F20*E20) -> 1530940 | I20: Indri
B21: Prnata Sumbedaya Manusia Penyedia | C21: Fungsional | D21: 6 | E21: 8 | F21: 1 | G21: 382735 | H21: =SUM(G21*F21*E21) -> 3061880
C22: Pelaksana | D22: 6 | E22: 12 | F22: 1 | G22: 382735 | H22: =SUM(G22*F22*E22) -> 4592820 | I22: Cia
B23: Mutasi/Pangkat | C23: Pelaksana | D23: 7 | E23: 12 | F23: 3 | G23: 440438 | H23: =SUM(G23*F23*E23) -> 15855768 | I23: Una/Sapar/Khalil
C24: Pelaksana | D24: 7 | E24: 4 | F24: 1 | G24: 440438 | H24: =SUM(G24*F24*E24) -> 1761752 | I24: Tri
C25: Fungsional | D25: 8 | E25: 8 | F25: 1 | G25: 499535 | H25: =SUM(G25*F25*E25) -> 3996280
C26: Pelaksana | D26: 6 | E26: 4 | F26: 1 | G26: 382735 | H26: =SUM(G26*F26*E26) -> 1530940 | I26: Nasma
C27: Fungsional | D27: 10 | E27: 8 | F27: 1 | G27: 620474 | H27: =SUM(G27*F27*E27) -> 4963792
C28: Pelaksana | D28: 6 | E28: 4 | F28: 1 | G28: 382735 | H28: =SUM(G28*F28*E28) -> 1530940 | I28: Ica
C29: Funsional | D29: 6 | E29: 8 | F29: 1 | G29: 382735 | H29: =SUM(G29*F29*E29) -> 3061880
C30: Fungsional | D30: 6 | E30: 12 | F30: 1 | G30: 382735 | H30: =SUM(G30*F30*E30) -> 4592820 | I30: Murni
B31: Diklat | C31: Pelaksana | D31: 7 | E31: 4 | F31: 1 | G31: 440438 | H31: =SUM(G31*F31*E31) -> 1761752 | I31: Ade
C32: Fungsional | D32: 10 | E32: 8 | F32: 1 | G32: 620474 | H32: =SUM(G32*F32*E32) -> 4963792
C33: Pelaksana | D33: 6 | E33: 12 | F33: 2 | G33: 382735 | H33: =SUM(G33*F33*E33) -> 9185640 | I33: Maqfur/Fhmi
C34: Pelaksana | D34: 6 | E34: 4 | F34: 1 | G34: 382735 | H34: =SUM(G34*F34*E34) -> 1530940 | I34: wawan
C35: Fungsional | D35: 8 | E35: 8 | F35: 1 | G35: 499535 | H35: =SUM(G35*F35*E35) -> 3996280
C36: Pelaksana | D36: 5 | E36: 12 | F36: 1 | G36: 319202 | H36: =SUM(G36*F36*E36) -> 3830424 | I36: indah
B37: PIK | C37: Pelaksana | D37: 7 | E37: 4 | F37: 1 | G37: 440438 | H37: =SUM(G37*F37*E37) -> 1761752 | I37: Ammang
C38: Fungsional | D38: 10 | E38: 8 | F38: 1 | G38: 620474 | H38: =SUM(G38*F38*E38) -> 4963792
C39: Pelaksana | D39: 7 | E39: 4 | F39: 1 | G39: 440438 | H39: =SUM(G39*F39*E39) -> 1761752 | I39: Nawir
C40: Fungsional | D40: 8 | E40: 8 | F40: 1 | G40: 499535 | H40: =SUM(G40*F40*E40) -> 3996280
C41: Pelaksana | D41: 7 | E41: 12 | F41: 2 | G41: 440438 | H41: =SUM(G41*F41*E41) -> 10570512 | I41: wiwi/Shalsa
C42: Pelaksana | D42: 6 | E42: 12 | F42: 1 | G42: 382735 | H42: =SUM(G42*F42*E42) -> 4592820 | I42: Sahal
...

Sheet Sheet5
B1: Nama Pegawai | C1: PPh 21
A2: 7604030507720001 | B2: Drs. SARIANTO | C2: 870838 | D2: 5805587
A3: 7604042810810001 | B3: MUHAMMAD BAHRUM.S.Sos | C3: 569755 | D3: 3798368
A4: 7604040711740002 | B4: ZETH DIANTO N.G, S.IP, M.Si | C4: 573486 | D4: 3823244
A5: 7604061810860003 | B5: MUHAMMAD NARWIS, S.STP., MA. | C5: 571764 | D5: 3811763
A6: 7604044808740001 | B6: ANDI SYAMSIAH, SE | C6: 123064 | D6: 2461287
A7: 7604143112760014 | B7: AKHSAN, S.IP | C7: 97869 | D7: 1957388
A8: 7604041209690004 | B8: R I D W A N, S.Sos | C8: 122608 | D8: 2452163
A9: 7604062404680001 | B9: AMIR SAPIRIHAR, S.Sos | C9: 442623 | D9: 4426227
A10: 7604040804830004 | B10: ARY ARFAN, SAP, M.Si | C10: 121103 | D10: 2422064
A11: 7604040308860004 | B11: MUKTI FAHDIANSYAH, S.STP | C11: 365982 | D11: 2439877
A12: 7604043112690100 | B12: KHALIL ACO, S.Sos | C12: 85005 | D12: 1700095
A13: 7371101901690004 | B13: A I D I L, S.Sos | C13: 0 | D13: 0
... A48: 7316095210980001 | B48: NURHIDAYA RUSMAN, S.Kom | C48: 78691 | D48: 1573823
A49: 7602075203990001 | B49: WAHYUNI, S.T | C49: 78572 | D49: 1571449 | H49: 55328 | K49: 1106557
A50: 7601031406980004 | B50: MUH NURHUZAIN R, S.T | C50: 79008 | D50: 1580153 | H50: 55328 | I50: =SUM(H49:H50) -> 110656 | J50: 110656 | K50: 1106557
A51: 7604025212000003 | B51: SULPIANA, S.T | C51: 78770 | D51: 1575406 | H51: 165983 | I51: =SUM(H51:H52) -> 331966 | J51: 331967
A52: 7604046505990007 | B52: NUR AWALIA. S. Z. ABIDIN, S. Kom | C52: 78810 | D52: 1576197 | H52: 165983 | I52: =SUM(I50:I51) -> 442622 | J52: =SUM(J50:J51) -> 442623
A53: 7315031807950002 | B53: ARIYANTO DWI PUTRA, S.T | C53: 78256 | D53: 1565119 | H53: =SUM(H49:H52) -> 442622
A54: 7605015605000001 | B54: FATIHIA, S.A.P | C54: 79008 | D54: 1580153
C55: =SUM(C2:C54) -> 7085687 | D55: =SUM(D2:D54) -> 99441276
